Workbook

Sheet BudgetBuddy Test Cases
A1: BudgetBuddy - Functional Test Cases
A2: Module | B2: Test Case No | C2: Test Case Scenario | D2: Test Input / Preconditions | E2: Expected Output | F2: Actual Output | G2: Result (Pass/Fail)
A3: Registration & Verification | B3: REG1 | C3: Successful registration | D3: Valid full name, unique email, strong password | E3: Account is created and a verification code is sent to the registered email. | F3: Not Executed | G3: Not Executed
B4: REG2 | C4: Reject duplicate email | D4: Email already registered | E4: Registration is rejected with a clear duplicate-email message. | F4: Not Executed | G4: Not Executed
B5: REG3 | C5: Reject invalid email | D5: Email: user@invalid | E5: Email-format validation is shown and no account is created. | F5: Not Executed | G5: Not Executed
B6: REG4 | C6: Reject weak password | D6: Password missing required length/complexity | E6: Password validation is shown and no account is created. | F6: Not Executed | G6: Not Executed
B7: REG5 | C7: Reject missing required fields | D7: Blank name, email, or password | E7: Required-field validation is displayed. | F7: Not Executed | G7: Not Executed
B8: REG6 | C8: Verify email with valid code | D8: Registered email and active verification code | E8: Account becomes verified and can log in. | F8: Not Executed | G8: Not Executed
B9: REG7 | C9: Reject invalid verification code | D9: Registered email and incorrect code | E9: Verification fails without activating the account. | F9: Not Executed | G9: Not Executed
B10: REG8 | C10: Reject expired verification code | D10: Registered email and expired code | E10: User is told the code expired and account remains unverified. | F10: Not Executed | G10: Not Executed
A11: Login & Session | B11: LOG1 | C11: Successful Free User login | D11: Verified Free User credentials | E11: Login succeeds, JWT is stored, and Overview opens. | F11: Not Executed | G11: Not Executed
B12: LOG2 | C12: Successful Premium User login | D12: Verified Premium User credentials | E12: Login succeeds and Overview opens with Premium access available. | F12: Not Executed | G12: Not Executed
B13: LOG3 | C13: Successful Admin login | D13: Verified Admin credentials | E13: Login succeeds and Overview opens; Admin navigation is available. | F13: Not Executed | G13: Not Executed
B14: LOG4 | C14: Reject incorrect password | D14: Valid email and incorrect password | E14: Login is rejected with an invalid-credentials message. | F14: Not Executed | G14: Not Executed
B15: LOG5 | C15: Reject unknown email | D15: Unregistered email and any password | E15: Login is rejected without revealing sensitive account details. | F15: Not Executed | G15: Not Executed
B16: LOG6 | C16: Reject unverified account | D16: Correct credentials for unverified account | E16: Access is denied until email verification is completed. | F16: Not Executed | G16: Not Executed
B17: LOG7 | C17: Protected route without token | D17: Open /dashboard without JWT | E17: User is redirected to Login. | F17: Not Executed | G17: Not Executed
B18: LOG8 | C18: Expired or invalid token | D18: Call a protected API with invalid/expired JWT | E18: API returns 401 and the client clears the invalid session. | F18: Not Executed | G18: Not Executed
B19: LOG9 | C19: Logout | D19: Click Logout while authenticated | E19: JWT is removed and the user returns to Login. | F19: Not Executed | G19: Not Executed
B20: LOG10 | C20: Deactivated account | D20: Valid credentials for an inactive account | E20: Protected access is rejected with an account-deactivated message. | F20: Not Executed | G20: Not Executed
A21: Overview | B21: OVR1 | C21: Overview loads summary | D21: Authenticated user with financial records | E21: Balance, income, expenses, and savings match that user's data. | F21: Not Executed | G21: Not Executed
B22: OVR2 | C22: Overview empty state | D22: Authenticated user with no records | E22: Zero-value summary and appropriate empty states render without errors. | F22: Not Executed | G22: Not Executed
B23: OVR3 | C23: Month filter updates Overview | D23: Choose a different month | E23: Summary, charts, and transactions update for the selected month. | F23: Not Executed | G23: Not Executed
B24: OVR4 | C24: Recent transactions | D24: User has recent income and expenses | E24: Recent records are shown in correct chronological order and with correct types. | F24: Not Executed | G24: Not Executed
B25: OVR5 | C25: Budget progress | D25: Budget and matching expenses exist | E25: Budget progress reflects the selected user's spending. | F25: Not Executed | G25: Not Executed
B26: OVR6 | C26: Savings-goal progress | D26: Active savings goals exist | E26: Goal progress displays current saved and target amounts. | F26: Not Executed | G26: Not Executed
A27: Income | B27: INC1 | C27: Add income | D27: Valid source, positive amount, description, and account | E27: Income is saved for the authenticated user and totals update. | F27: Not Executed | G27: Not Executed
B28: INC2 | C28: Reject zero or negative income | D28: Amount: 0 or -100 | E28: Validation prevents the income record from being created. | F28: Not Executed | G28: Not Executed
B29: INC3 | C29: List own income only | D29: Two users each have income records | E29: Each user sees only their own income. | F29: Not Executed | G29: Not Executed
B30: INC4 | C30: Edit own income | D30: Change amount/source of owned record | E30: Record updates successfully and summaries recalculate. | F30: Not Executed | G30: Not Executed
B31: INC5 | C31: Prevent editing another user's income | D31: Use another user's income ID | E31: API returns not found/denied and the record is unchanged. | F31: Not Executed | G31: Not Executed
B32: INC6 | C32: Delete own income | D32: Delete an owned income record | E32: Record is removed and totals update. | F32: Not Executed | G32: Not Executed
A33: Expenses | B33: EXP1 | C33: Add expense | D33: Valid category, positive amount, description, and account | E33: Expense is saved for the authenticated user and totals update. | F33: Not Executed | G33: Not Executed
B34: EXP2 | C34: Reject invalid expense amount | D34: Amount: 0 or negative | E34: Validation prevents the expense record from being created. | F34: Not Executed | G34: Not Executed
B35: EXP3 | C35: Require expense description | D35: Valid amount but missing required description | E35: Validation explains that the description is required. | F35: Not Executed | G35: Not Executed
B36: EXP4 | C36: List own expenses only | D36: Two users each have expense records | E36: Each user sees only their own expenses. | F36: Not Executed | G36: Not Executed
B37: EXP5 | C37: Edit own expense | D37: Update owned expense amount/category | E37: Expense updates and affected totals/budgets recalculate. | F37: Not Executed | G37: Not Executed
B38: EXP6 | C38: Prevent editing another user's expense | D38: Use another user's expense ID | E38: API returns not found/denied and data remains unchanged. | F38: Not Executed | G38: Not Executed
B39: EXP7 | C39: Delete own expense | D39: Delete an owned expense | E39: Expense is removed and related totals update. | F39: Not Executed | G39: Not Executed
B40: EXP8 | C40: Budget threshold notification | D40: Expense causes category spending to exceed budget | E40: A single budget alert is generated with the correct message. | F40: Not Executed | G40: Not Executed
...

Sheet Test Summary
A1: BudgetBuddy Test Summary
A2: Module | B2: Number of Cases | C2: Executed | D2: Pass Rate
A3: Registration & Verification | B3: 8 | C3: =COUNTIFS('BudgetBuddy Test Cases'!B:B,"REG*",'BudgetBuddy Test Cases'!G:G,"<>Not Executed") | D3: =IF(C3=0,"Not Executed",COUNTIFS('BudgetBuddy Test Cases'!B:B,"REG*",'BudgetBuddy Test Cases'!G:G,"Pass")/C3)
A4: Login & Session | B4: 10 | C4: =COUNTIFS('BudgetBuddy Test Cases'!B:B,"LOG*",'BudgetBuddy Test Cases'!G:G,"<>Not Executed") | D4: =IF(C4=0,"Not Executed",COUNTIFS('BudgetBuddy Test Cases'!B:B,"LOG*",'BudgetBuddy Test Cases'!G:G,"Pass")/C4)
A5: Overview | B5: 6 | C5: =COUNTIFS('BudgetBuddy Test Cases'!B:B,"OVR*",'BudgetBuddy Test Cases'!G:G,"<>Not Executed") | D5: =IF(C5=0,"Not Executed",COUNTIFS('BudgetBuddy Test Cases'!B:B,"OVR*",'BudgetBuddy Test Cases'!G:G,"Pass")/C5)
A6: Income | B6: 6 | C6: =COUNTIFS('BudgetBuddy Test Cases'!B:B,"INC*",'BudgetBuddy Test Cases'!G:G,"<>Not Executed") | D6: =IF(C6=0,"Not Executed",COUNTIFS('BudgetBuddy Test Cases'!B:B,"INC*",'BudgetBuddy Test Cases'!G:G,"Pass")/C6)
A7: Expenses | B7: 8 | C7: =COUNTIFS('BudgetBuddy Test Cases'!B:B,"EXP*",'BudgetBuddy Test Cases'!G:G,"<>Not Executed") | D7: =IF(C7=0,"Not Executed",COUNTIFS('BudgetBuddy Test Cases'!B:B,"EXP*",'BudgetBuddy Test Cases'!G:G,"Pass")/C7)
A8: Accounts | B8: 5 | C8: =COUNTIFS('BudgetBuddy Test Cases'!B:B,"ACC*",'BudgetBuddy Test Cases'!G:G,"<>Not Executed") | D8: =IF(C8=0,"Not Executed",COUNTIFS('BudgetBuddy Test Cases'!B:B,"ACC*",'BudgetBuddy Test Cases'!G:G,"Pass")/C8)
A9: Budgets | B9: 7 | C9: =COUNTIFS('BudgetBuddy Test Cases'!B:B,"BUD*",'BudgetBuddy Test Cases'!G:G,"<>Not Executed") | D9: =IF(C9=0,"Not Executed",COUNTIFS('BudgetBuddy Test Cases'!B:B,"BUD*",'BudgetBuddy Test Cases'!G:G,"Pass")/C9)
A10: Savings Goals | B10: 7 | C10: =COUNTIFS('BudgetBuddy Test Cases'!B:B,"GOL*",'BudgetBuddy Test Cases'!G:G,"<>Not Executed") | D10: =IF(C10=0,"Not Executed",COUNTIFS('BudgetBuddy Test Cases'!B:B,"GOL*",'BudgetBuddy Test Cases'!G:G,"Pass")/C10)
A11: Analytics | B11: 14 | C11: =COUNTIFS('BudgetBuddy Test Cases'!B:B,"ANA*",'BudgetBuddy Test Cases'!G:G,"<>Not Executed") | D11: =IF(C11=0,"Not Executed",COUNTIFS('BudgetBuddy Test Cases'!B:B,"ANA*",'BudgetBuddy Test Cases'!G:G,"Pass")/C11)
A12: Reports & Export | B12: 5 | C12: =COUNTIFS('BudgetBuddy Test Cases'!B:B,"RPT*",'BudgetBuddy Test Cases'!G:G,"<>Not Executed") | D12: =IF(C12=0,"Not Executed",COUNTIFS('BudgetBuddy Test Cases'!B:B,"RPT*",'BudgetBuddy Test Cases'!G:G,"Pass")/C12)
A13: Notifications | B13: 5 | C13: =COUNTIFS('BudgetBuddy Test Cases'!B:B,"NOT*",'BudgetBuddy Test Cases'!G:G,"<>Not Executed") | D13: =IF(C13=0,"Not Executed",COUNTIFS('BudgetBuddy Test Cases'!B:B,"NOT*",'BudgetBuddy Test Cases'!G:G,"Pass")/C13)
A14: Profile & Settings | B14: 5 | C14: =COUNTIFS('BudgetBuddy Test Cases'!B:B,"PRO*",'BudgetBuddy Test Cases'!G:G,"<>Not Executed") | D14: =IF(C14=0,"Not Executed",COUNTIFS('BudgetBuddy Test Cases'!B:B,"PRO*",'BudgetBuddy Test Cases'!G:G,"Pass")/C14)
A15: Premium Membership | B15: 5 | C15: =COUNTIFS('BudgetBuddy Test Cases'!B:B,"PRE*",'BudgetBuddy Test Cases'!G:G,"<>Not Executed") | D15: =IF(C15=0,"Not Executed",COUNTIFS('BudgetBuddy Test Cases'!B:B,"PRE*",'BudgetBuddy Test Cases'!G:G,"Pass")/C15)
A16: Admin & Role Access | B16: 12 | C16: =COUNTIFS('BudgetBuddy Test Cases'!B:B,"ADM*",'BudgetBuddy Test Cases'!G:G,"<>Not Executed") | D16: =IF(C16=0,"Not Executed",COUNTIFS('BudgetBuddy Test Cases'!B:B,"ADM*",'BudgetBuddy Test Cases'!G:G,"Pass")/C16)
A17: Navigation & Compatibility | B17: 5 | C17: =COUNTIFS('BudgetBuddy Test Cases'!B:B,"NAV*",'BudgetBuddy Test Cases'!G:G,"<>Not Executed") | D17: =IF(C17=0,"Not Executed",COUNTIFS('BudgetBuddy Test Cases'!B:B,"NAV*",'BudgetBuddy Test Cases'!G:G,"Pass")/C17)
A18: TOTAL | B18: 108
